<?xml version="1.0"?>
<robot name="test_robot">
  <!-- <material name="red">
    <color rgba="1.0 0.0 0.0 1.0"/>
  </material> -->
  
  <link name="base_link"/>

  <joint name="body1_joint" type="fixed">
    <parent link="base_link"/>
    <child  link="body1_link"/>
  </joint>
  <joint name="body2_joint" type="revolute">
    <parent link="body1_link"/>
    <child  link="body2_link"/>
    <origin xyz="0 0 0.1203" rpy="0 0 0"/>
    <limit lower="-1.5" upper="1.5" effort="0" velocity="0"/>
    <axis xyz="0.0 0.0 1.0"/>
  </joint>
  <joint name="body3_joint" type="revolute">
    <parent link="body2_link"/>
    <child  link="body3_link"/>
    <origin xyz="0.05 0 0.115" rpy="0 0 0"/>
    <limit lower="-1.5" upper="1.5" effort="0" velocity="0"/>
    <axis xyz="1.0 0.0 0.0"/>
  </joint>
  <joint name="body4_joint" type="revolute">
    <parent link="body3_link"/>
    <child  link="body4_link"/>
    <origin xyz="0 0 0.280" rpy="0 0 0"/>
    <limit lower="-1.5" upper="1.5" effort="0" velocity="0"/>
    <axis xyz="1.0 0.0 0.0"/>
  </joint>
  <joint name="body5_joint" type="revolute">
    <parent link="body4_link"/>
    <child  link="body5_link"/>
    <origin xyz="-0.05 0 0.140" rpy="0 0 0"/>
    <limit lower="-1.5" upper="1.5" effort="0" velocity="0"/>
    <axis xyz="0.0 0.0 1.0"/>
  </joint>
  <joint name="body6_joint" type="revolute">
    <parent link="body5_link"/>
    <child  link="body6_link"/>
    <origin xyz="0 0.05 0.105" rpy="0 0 0"/>
    <limit lower="-1.5" upper="1.5" effort="0" velocity="0"/>
    <axis xyz="0.0 1.0 0.0"/>
  </joint>
  <joint name="body7_joint" type="revolute">
    <parent link="body6_link"/>
    <child  link="body7_link"/>
    <origin xyz="0 0 0.105" rpy="0 0 0"/>
    <limit lower="-1.5" upper="1.5" effort="0" velocity="0"/>
    <axis xyz="0.0 0.0 1.0"/>
  </joint>

  <link name="body1_link">
    <visual>
      <geometry>
        <box size="0.08 0.08 0.1203"/>
      </geometry>
      <origin xyz="0 0 0.06015" rpy="0 0 0"/>
        <material name="red">
          <color rgba="1.0 0.0 0.0 1.0"/>
        </material>
    </visual>
    <!-- gazebo用に追加 -->
    <inertial>
     <origin xyz="0 0 0.06015" rpy="0 0 0"/>
     <mass value="1"/>
     <inertia ixx="0.1"  ixy="0"  ixz="0" iyy="0.1" iyz="0" izz="0.1" />
   </inertial>
    <collision>
     <geometry>
       <box size="0.08 0.08 0.1203" />
     </geometry>
     <origin xyz="0 0 0.06015" rpy="0 0 0"/>
   </collision>
   <!--  -->
  </link>
  <link name="body2_link">
    <visual>
      <geometry>
        <box size="0.05 0.05 0.115"/>
      </geometry>
      <origin xyz="0 0 0.0575" rpy="0 0 0"/>
        <material name="green">
          <color rgba="0.0 1.0 0.0 1.0"/>
        </material>
    </visual>
    <!-- gazebo用に追加 -->
    <inertial>
     <origin xyz="0 0 0.0575" rpy="0 0 0"/>
     <mass value="1"/>
     <inertia ixx="0.1"  ixy="0"  ixz="0" iyy="0.1" iyz="0" izz="0.1" />
   </inertial>
    <collision>
     <geometry>
       <box size="0.05 0.05 0.115" />
     </geometry>
     <origin xyz="0 0 0.0575" rpy="0 0 0"/>
   </collision>
   <!--  -->
  </link>
    <link name="body3_link">
    <visual>
      <geometry>
        <box size="0.05 0.05 0.280"/>
      </geometry>
      <origin xyz="0 0 0.140" rpy="0 0 0"/>
        <material name="blue">
          <color rgba="0.0 0.0 1.0 1.0"/>
        </material>
    </visual>
    <!-- gazebo用に追加 -->
    <inertial>
     <origin xyz="0 0 0.140" rpy="0 0 0"/>
     <mass value="1"/>
     <inertia ixx="0.1"  ixy="0"  ixz="0" iyy="0.1" iyz="0" izz="0.1" />
   </inertial>
    <collision>
     <geometry>
       <box size="0.05 0.05 0.280" />
     </geometry>
     <origin xyz="0 0 0.140" rpy="0 0 0"/>
   </collision>
   <!--  -->
  </link>
    <link name="body4_link">
    <visual>
      <geometry>
        <box size="0.05 0.05 0.140"/>
      </geometry>
      <origin xyz="0 0 0.07" rpy="0 0 0"/>
        <material name="purple">
          <color rgba="0.5 0.0 0.5 1.0"/>
        </material>
    </visual>
    <!-- gazebo用に追加 -->
    <inertial>
     <origin xyz="0 0 0.07" rpy="0 0 0"/>
     <mass value="1"/>
     <inertia ixx="0.1"  ixy="0"  ixz="0" iyy="0.1" iyz="0" izz="0.1" />
   </inertial>
    <collision>
     <geometry>
       <box size="0.05 0.05 0.140" />
     </geometry>
     <origin xyz="0 0 0.07" rpy="0 0 0"/>
   </collision>
   <!--  -->
  </link>
    <link name="body5_link">
    <visual>
      <geometry>
        <box size="0.05 0.05 0.105"/>
      </geometry>
      <origin xyz="0 0 0.0525" rpy="0 0 0"/>
        <material name="fuchsia">
          <color rgba="1.0 0.0 1.0 1.0"/>
        </material>
    </visual>
    <!-- gazebo用に追加 -->
    <inertial>
     <origin xyz="0 0 0.0525" rpy="0 0 0"/>
     <mass value="1"/>
     <inertia ixx="0.1"  ixy="0"  ixz="0" iyy="0.1" iyz="0" izz="0.1" />
   </inertial>
    <collision>
     <geometry>
       <box size="0.05 0.05 0.105" />
     </geometry>
     <origin xyz="0 0 0.0525" rpy="0 0 0"/>
   </collision>
   <!--  -->
  </link>
    <link name="body6_link">
    <visual>
      <geometry>
        <box size="0.05 0.05 0.105"/>
      </geometry>
      <origin xyz="0 0 0.0525" rpy="0 0 0"/>
        <material name="yellow">
          <color rgba="1.0 1.0 0.0 1.0"/>
        </material>
    </visual>
    <!-- gazebo用に追加 -->
    <inertial>
     <origin xyz="0 0 0.0525" rpy="0 0 0"/>
     <mass value="1"/>
     <inertia ixx="0.1"  ixy="0"  ixz="0" iyy="0.1" iyz="0" izz="0.1" />
   </inertial>
    <collision>
     <geometry>
       <box size="0.05 0.05 0.105" />
     </geometry>
     <origin xyz="0 0 0.0525" rpy="0 0 0"/>
   </collision>
   <!--  -->
  </link>
  <link name="body7_link">
    <visual>
      <geometry>
        <box size="0.05 0.05 0.130"/>
      </geometry>
      <origin xyz="0 0 0.065" rpy="0 0 0"/>
        <material name="terl">
          <color rgba="0.0 0.5 0.5 1.0"/>
        </material>
    </visual>
    <!-- gazebo用に追加 -->
    <inertial>
     <origin xyz="0 0 0.065" rpy="0 0 0"/>
     <mass value="1"/>
     <inertia ixx="0.1"  ixy="0"  ixz="0" iyy="0.1" iyz="0" izz="0.1" />
   </inertial>
    <collision>
     <geometry>
       <box size="0.05 0.05 0.130" />
     </geometry>
     <origin xyz="0 0 0.065" rpy="0 0 0"/>
   </collision>
   <!--  -->
  </link>
</robot>
