<?xml version="1.0"?>
<robot name="arm_Gen3_robot">

  <link name="world"/>
  <link name="base_link"/>
  <!--台座と作業台（world）をつなぐjoint-->
  <joint name="base_joint" type="fixed">
    <parent link="world"/>
    <child link="base_link"/> 
  </joint>

  <joint name="body1_joint" type="fixed">
    <parent link="base_link"/>
    <child  link="body1_link"/>
  </joint>
  <joint name="body2_joint" type="revolute">
    <parent link="body1_link"/>
    <child  link="body2_link"/>
    <origin xyz="0 0 0.1203" rpy="0 0 0"/>
    <limit lower="-1.5" upper="1.5" effort="0" velocity="0"/>
    <axis xyz="0.0 0.0 1.0"/>
  </joint>
  <joint name="body3_joint" type="revolute">
    <parent link="body2_link"/>
    <child  link="body3_link"/>
    <origin xyz="0.05 0 0.115" rpy="0 0 0"/>
    <limit lower="-1.5" upper="1.5" effort="0" velocity="0"/>
    <axis xyz="1.0 0.0 0.0"/>
  </joint>
  <joint name="body4_joint" type="revolute">
    <parent link="body3_link"/>
    <child  link="body4_link"/>
    <origin xyz="0 0 0.280" rpy="0 0 0"/>
    <limit lower="-1.5" upper="1.5" effort="0" velocity="0"/>
    <axis xyz="1.0 0.0 0.0"/>
  </joint>
  <joint name="body5_joint" type="revolute">
    <parent link="body4_link"/>
    <child  link="body5_link"/>
    <origin xyz="-0.05 0 0.140" rpy="0 0 0"/>
    <limit lower="-1.5" upper="1.5" effort="0" velocity="0"/>
    <axis xyz="0.0 0.0 1.0"/>
  </joint>
  <joint name="body6_joint" type="revolute">
    <parent link="body5_link"/>
    <child  link="body6_link"/>
    <origin xyz="0 0.05 0.105" rpy="0 0 0"/>
    <limit lower="-1.5" upper="1.5" effort="0" velocity="0"/>
    <axis xyz="0.0 1.0 0.0"/>
  </joint>
  <joint name="body7_joint" type="revolute">
    <parent link="body6_link"/>
    <child  link="body7_link"/>
    <origin xyz="0 0 0.105" rpy="0 0 0"/>
    <limit lower="-1.5" upper="1.5" effort="0" velocity="0"/>
    <axis xyz="0.0 0.0 1.0"/>
  </joint>

  
  <transmission name="body2_trans">
    <type>transmission_interface/SimpleTransmission</type>
    <joint name="body2_joint">
      <hardwareInterface>hardware_interface/EffortJointInterface</hardwareInterface>
    </joint>
    <actuator name="body2_motor">
       <hardwareInterface>hardware_interface/EffortJointInterface</hardwareInterface>
       <mechanismReduction>1</mechanismReduction>
    </actuator>
  </transmission>
  <transmission name="body3_trans">
    <type>transmission_interface/SimpleTransmission</type>
    <joint name="body3_joint">
      <hardwareInterface>hardware_interface/EffortJointInterface</hardwareInterface>
    </joint>
    <actuator name="body3_motor">
       <hardwareInterface>hardware_interface/EffortJointInterface</hardwareInterface>
       <mechanismReduction>1</mechanismReduction>
    </actuator>
  </transmission>
  <transmission name="body4_trans">
    <type>transmission_interface/SimpleTransmission</type>
    <joint name="body4_joint">
      <hardwareInterface>hardware_interface/EffortJointInterface</hardwareInterface>
    </joint>
    <actuator name="body4_motor">
       <hardwareInterface>hardware_interface/EffortJointInterface</hardwareInterface>
       <mechanismReduction>1</mechanismReduction>
    </actuator>
  </transmission>
  <transmission name="body5_trans">
    <type>transmission_interface/SimpleTransmission</type>
    <joint name="body5_joint">
      <hardwareInterface>hardware_interface/EffortJointInterface</hardwareInterface>
    </joint>
    <actuator name="body5_motor">
       <hardwareInterface>hardware_interface/EffortJointInterface</hardwareInterface>
       <mechanismReduction>1</mechanismReduction>
    </actuator>
  </transmission>
  <transmission name="body6_trans">
    <type>transmission_interface/SimpleTransmission</type>
    <joint name="body6_joint">
      <hardwareInterface>hardware_interface/EffortJointInterface</hardwareInterface>
    </joint>
    <actuator name="body6_motor">
       <hardwareInterface>hardware_interface/EffortJointInterface</hardwareInterface>
       <mechanismReduction>1</mechanismReduction>
    </actuator>
  </transmission>
  <transmission name="body7_trans">
    <type>transmission_interface/SimpleTransmission</type>
    <joint name="body7_joint">
      <hardwareInterface>hardware_interface/EffortJointInterface</hardwareInterface>
    </joint>
    <actuator name="body7_motor">
       <hardwareInterface>hardware_interface/EffortJointInterface</hardwareInterface>
       <mechanismReduction>1</mechanismReduction>
    </actuator>
  </transmission>



  <link name="body1_link">
    <visual>
      <geometry>
        <box size="0.08 0.08 0.1203"/>
      </geometry>
      <origin xyz="0 0 0.06015" rpy="0 0 0"/>
        <material name="red">
          <color rgba="1.0 0.0 0.0 1.0"/>
        </material>
    </visual>
    <!-- gazebo用に追加 -->
    <inertial>
     <origin xyz="0 0 0.06015" rpy="0 0 0"/>
     <mass value="1"/>
     <inertia ixx="0.1"  ixy="0"  ixz="0" iyy="0.1" iyz="0" izz="0.1" />
   </inertial>
    <collision>
     <geometry>
       <box size="0.08 0.08 0.1203" />
     </geometry>
     <origin xyz="0 0 0.06015" rpy="0 0 0"/>
   </collision>
   <!--  -->
  </link>
  <link name="body2_link">
    <visual>
      <geometry>
        <box size="0.05 0.05 0.115"/>
      </geometry>
      <origin xyz="0 0 0.0575" rpy="0 0 0"/>
        <material name="green">
          <color rgba="0.0 1.0 0.0 1.0"/>
        </material>
    </visual>
    <!-- gazebo用に追加 -->
    <inertial>
     <origin xyz="0 0 0.0575" rpy="0 0 0"/>
     <mass value="1"/>
     <inertia ixx="0.1"  ixy="0"  ixz="0" iyy="0.1" iyz="0" izz="0.1" />
   </inertial>
    <collision>
     <geometry>
       <box size="0.05 0.05 0.115" />
     </geometry>
     <origin xyz="0 0 0.0575" rpy="0 0 0"/>
   </collision>
   <!--  -->
  </link>
    <link name="body3_link">
    <visual>
      <geometry>
        <box size="0.05 0.05 0.280"/>
      </geometry>
      <origin xyz="0 0 0.140" rpy="0 0 0"/>
        <material name="blue">
          <color rgba="0.0 0.0 1.0 1.0"/>
        </material>
    </visual>
    <!-- gazebo用に追加 -->
    <inertial>
     <origin xyz="0 0 0.140" rpy="0 0 0"/>
     <mass value="1"/>
     <inertia ixx="0.1"  ixy="0"  ixz="0" iyy="0.1" iyz="0" izz="0.1" />
   </inertial>
    <collision>
     <geometry>
       <box size="0.05 0.05 0.280" />
     </geometry>
     <origin xyz="0 0 0.140" rpy="0 0 0"/>
   </collision>
   <!--  -->
  </link>
    <link name="body4_link">
    <visual>
      <geometry>
        <box size="0.05 0.05 0.140"/>
      </geometry>
      <origin xyz="0 0 0.07" rpy="0 0 0"/>
        <material name="purple">
          <color rgba="0.5 0.0 0.5 1.0"/>
        </material>
    </visual>
    <!-- gazebo用に追加 -->
    <inertial>
     <origin xyz="0 0 0.07" rpy="0 0 0"/>
     <mass value="1"/>
     <inertia ixx="0.1"  ixy="0"  ixz="0" iyy="0.1" iyz="0" izz="0.1" />
   </inertial>
    <collision>
     <geometry>
       <box size="0.05 0.05 0.140" />
     </geometry>
     <origin xyz="0 0 0.07" rpy="0 0 0"/>
   </collision>
   <!--  -->
  </link>
    <link name="body5_link">
    <visual>
      <geometry>
        <box size="0.05 0.05 0.105"/>
      </geometry>
      <origin xyz="0 0 0.0525" rpy="0 0 0"/>
        <material name="fuchsia">
          <color rgba="1.0 0.0 1.0 1.0"/>
        </material>
    </visual>
    <!-- gazebo用に追加 -->
    <inertial>
     <origin xyz="0 0 0.0525" rpy="0 0 0"/>
     <mass value="1"/>
     <inertia ixx="0.1"  ixy="0"  ixz="0" iyy="0.1" iyz="0" izz="0.1" />
   </inertial>
    <collision>
     <geometry>
       <box size="0.05 0.05 0.105" />
     </geometry>
     <origin xyz="0 0 0.0525" rpy="0 0 0"/>
   </collision>
   <!--  -->
  </link>
    <link name="body6_link">
    <visual>
      <geometry>
        <box size="0.05 0.05 0.105"/>
      </geometry>
      <origin xyz="0 0 0.0525" rpy="0 0 0"/>
        <material name="yellow">
          <color rgba="1.0 1.0 0.0 1.0"/>
        </material>
    </visual>
    <!-- gazebo用に追加 -->
    <inertial>
     <origin xyz="0 0 0.0525" rpy="0 0 0"/>
     <mass value="1"/>
     <inertia ixx="0.1"  ixy="0"  ixz="0" iyy="0.1" iyz="0" izz="0.1" />
   </inertial>
    <collision>
     <geometry>
       <box size="0.05 0.05 0.105" />
     </geometry>
     <origin xyz="0 0 0.0525" rpy="0 0 0"/>
   </collision>
   <!--  -->
  </link>
  <link name="body7_link">
    <visual>
      <geometry>
        <box size="0.05 0.05 0.130"/>
      </geometry>
      <origin xyz="0 0 0.065" rpy="0 0 0"/>
        <material name="terl">
          <color rgba="0.0 0.5 0.5 1.0"/>
        </material>
    </visual>
    <!-- gazebo用に追加 -->
    <inertial>
     <origin xyz="0 0 0.065" rpy="0 0 0"/>
     <mass value="1"/>
     <inertia ixx="0.1"  ixy="0"  ixz="0" iyy="0.1" iyz="0" izz="0.1" />
   </inertial>
    <collision>
     <geometry>
       <box size="0.05 0.05 0.130" />
     </geometry>
     <origin xyz="0 0 0.065" rpy="0 0 0"/>
   </collision>
   <!--  -->
  </link>]
  <!--add_GazeboPlugin-->
  <gazebo>
    <plugin name="gazebo_ros_control" filename="libgazebo_ros_control.so">
      <robotNamespace>/arm_Gen3_robot</robotNamespace>
      <robotSimType>gazebo_ros_control/DefaultRobotHWSim</robotSimType>
      <legacyModeNS>true</legacyModeNS>
    </plugin>
    <!-- <plugin name="joint_state_publisher" filename="libgazebo_ros_joint_state_publisher.so">
      <jointName>arm1_joint, arm2_joint, arm3_joint</jointName>
    </plugin> -->
  </gazebo>
</robot>
