<?xml version="1.0"?>
<robot name="arm_robot">
  <link name="world"/>
  <!--台座と作業台（world）をつなぐjoint-->
  <joint name="base_joint" type="fixed">
    <parent link="world"/>
    <child link="base_link"/> 
  </joint>
  <!--台座のモデリング-->
  <link name="base_link">
  <!--慣性-->
    <inertial>
      <origin xyz="0 0 0.025" rpy="0 0 0"/>
      <mass value="1.0"/>
      <inertia ixx="0.0027" iyy="0.0027" izz="0.005" ixy="0" ixz="0" iyz="0"/>
    </inertial>
    <!--外観-->
    <visual>
      <origin xyz="0 0 0.025" rpy="0 0 0"/>
      <geometry>
        <cylinder radius="0.1" length="0.05"/>
      </geometry>
    </visual>
    <!--干渉-->
    <collision>
      <origin xyz="0 0 0.025" rpy="0 0 0"/>
      <geometry>
        <cylinder radius="0.1" length="0.05"/>
      </geometry>
    </collision>
  </link>
  <!--materialcolor-->
  <gazebo reference="base_link">
    <material>Gazebo/Red</material>
  </gazebo>
  <!--baseとarm1をつなぐjoint-->
  <joint name="arm1_joint" type="continuous">
    <parent link="base_link"/>
    <child link="arm1_link"/>
    <axis xyz="0 0 1"/>
    <origin xyz="0 0 0.05" rpy="0 0 0"/>
    <dynamics damping="0.1"/>
  </joint>
  <!--arm1トランスミッション-->
  <transmission name="arm1_trans">
    <type>transmission_interface/SimpleTransmission</type>
    <joint name="arm1_joint">
      <hardwareInterface>hardware_interface/EffortJointInterface</hardwareInterface>
    </joint>
    <actuator name="arm1_motor">
       <hardwareInterface>hardware_interface/EffortJointInterface</hardwareInterface>
       <mechanismReduction>1</mechanismReduction>
    </actuator>
  </transmission>
  <!--arm1のモデリング-->
  <link name="arm1_link">
  <!--慣性-->
    <inertial>
      <mass value="1.0"/>
      <origin xyz="0 0 0.0625" rpy="0 0 0"/>
      <inertia ixx="1.0" ixy="0.0" ixz="0.0" iyy="1.0" iyz="0.0" izz="1.0"/>
    </inertial>
    <!--外観-->
    <visual>
      <origin xyz="0 0 0.0625" rpy="0 0 0"/>
      <geometry>
        <box size="0.05 0.05 0.125"/>
      </geometry>
    </visual>
    <!--干渉-->
    <collision>
      <origin xyz="0 0 0.0625" rpy="0 0 0"/>
      <geometry>
        <box size="0.05 0.05 0.125"/>
      </geometry>
    </collision>
  </link>
  <!--materialcolor-->
  <gazebo reference="arm1_link">
    <material>Gazebo/Blue</material>
  </gazebo>
  <!--arm1とarm1_2をつなぐjoint-->
  <joint name="arm1_2_joint" type="fixed">
    <parent link="arm1_link"/>
    <child link="arm1_2_link"/>
  </joint>
  <!--arm2のモデリング-->
  <link name="arm1_2_link">
  <!--慣性-->
    <inertial>
      <mass value="1.0"/>
      <origin xyz="0 0.0625 0.1" rpy="0 0 0"/>
      <inertia ixx="1.0" ixy="0.0" ixz="0.0" iyy="1.0" iyz="0.0" izz="1.0"/>
    </inertial>
    <!--外観-->
    <visual>
      <origin xyz="0 0.0625 0.1" rpy="0 0 0"/>
      <geometry>
        <box size="0.05 0.075 0.05"/>
      </geometry>
    </visual>
    <!--干渉-->
    <collision>
      <origin xyz="0 0.0625 0.1" rpy="0 0 0"/>
      <geometry>
        <box size="0.05 0.075 0.05"/>
      </geometry>
    </collision>
  </link>
  <!--materialcolor-->
  <gazebo reference="arm1_2_link">
    <material>Gazebo/Blue</material>
  </gazebo>

  <!--arm1_2とarm2をつなぐjoint-->
  <joint name="arm2_joint" type="continuous">
    <parent link="arm1_2_link"/>
    <child link="arm2_link"/>
    <axis xyz="1 0 0"/>
    <origin xyz="0 0.1 0.1" rpy="0 0 0"/>
    <dynamics damping="0.1"/>
  </joint>
  <!--arm2トランスミッション-->
  <transmission name="arm2_trans">
    <type>transmission_interface/SimpleTransmission</type>
    <joint name="arm2_joint">
      <hardwareInterface>hardware_interface/EffortJointInterface</hardwareInterface>
    </joint>
    <actuator name="arm2_motor">
       <hardwareInterface>hardware_interface/EffortJointInterface</hardwareInterface>
       <mechanismReduction>1</mechanismReduction>
    </actuator>
  </transmission>
  <!--arm2のモデリング-->
  <link name="arm2_link">
  <!--慣性-->
    <inertial>
      <mass value="1.0"/>
      <origin xyz="0 0 0.2" rpy="0 0 0"/>
      <inertia ixx="1.0" ixy="0.0" ixz="0.0" iyy="1.0" iyz="0.0" izz="1.0"/>
    </inertial>
    <!--外観-->
    <visual>
      <origin xyz="0 0 0.2" rpy="0 0 0"/>
      <geometry>
        <box size="0.05 0.05 0.4"/>
      </geometry>
    </visual>
    <!--干渉-->
    <collision>
      <origin xyz="0 0 0.2" rpy="0 0 0"/>
      <geometry>
        <box size="0.05 0.05 0.4"/>
      </geometry>
    </collision>
  </link>
  <!--materialcolor-->
  <gazebo reference="arm2_link">
    <material>Gazebo/Red</material>
  </gazebo>






  <!--arm2とarm3をつなぐjoint-->
  <joint name="arm3_joint" type="continuous">
    <parent link="arm2_link"/>
    <child link="arm3_link"/>
    <axis xyz="1 0 0"/>
    <origin xyz="0 0 0.4" rpy="0 0 0"/>
    <dynamics damping="0.1"/>
  </joint>
  <!--arm3トランスミッション-->
  <transmission name="arm3_trans">
    <type>transmission_interface/SimpleTransmission</type>
    <joint name="arm3_joint">
      <hardwareInterface>hardware_interface/EffortJointInterface</hardwareInterface>
    </joint>
    <actuator name="arm3_motor">
       <hardwareInterface>hardware_interface/EffortJointInterface</hardwareInterface>
       <mechanismReduction>1</mechanismReduction>
    </actuator>
  </transmission>
  <!--arm3のモデリング-->
  <link name="arm3_link">
  <!--慣性-->
    <inertial>
      <mass value="1.0"/>
      <origin xyz="0 0 0.175" rpy="0 0 0"/>
      <inertia ixx="1.0" ixy="0.0" ixz="0.0" iyy="1.0" iyz="0.0" izz="1.0"/>
    </inertial>
    <!--外観-->
    <visual>
      <origin xyz="0 0 0.175" rpy="0 0 0"/>
      <geometry>
        <box size="0.05 0.05 0.35"/>
      </geometry>
    </visual>
    <!--干渉-->
    <collision>
      <origin xyz="0 0 0.175" rpy="0 0 0"/>
      <geometry>
        <box size="0.05 0.05 0.35"/>
      </geometry>
    </collision>
  </link>
  <!--materialcolor-->
  <gazebo reference="arm3_link">
    <material>Gazebo/Blue</material>
  </gazebo>

  <!--arm3とcameraをつなぐjoint-->
  <joint name="camera_joint" type="fixed">
    <parent link="arm3_link"/>
    <child link="camera_link"/>
    <origin xyz="0 0 0.35" rpy="1.57 -1.57 0"/>
  </joint>
  <!--cameraのモデリング-->
  <link name="camera_link">
  <!--慣性-->
    <inertial>
      <mass value="0"/>
      <origin xyz="0 0 0" rpy="0 0 0"/>
      <inertia ixx="0" ixy="0.0" ixz="0.0" iyy="0" iyz="0.0" izz="0"/>
    </inertial>
    <!--外観-->
    <visual>
      <origin xyz="0 0 0" rpy="0 0 0"/>
      <geometry>
        <box size="0 0 0"/>
      </geometry>
    </visual>
    <!--干渉-->
    <collision>
      <origin xyz="0 0 0" rpy="0 0 0"/>
      <geometry>
        <box size="0 0 0"/>
      </geometry>
    </collision>
  </link>
  <!--materialcolor-->
  <gazebo reference="camera_link">
    <material>Gazebo/Blue</material>
  </gazebo>
  
  <!-- camera plugin -->
  <gazebo reference="camera_link">
    <sensor type="camera" name="camera1">
        <alwaysOn>true</alwaysOn>
        <visualize>true</visualize>
        <update_rate>30.0</update_rate>
        <camera name="head">
            <horizontal_fov>1.3962634</horizontal_fov>
            <image>
                <width>800</width>
                <height>700</height>
                <format>R8G8B8</format>
            </image>
            <clip>
                <near>0.02</near>
                <far>300</far>
            </clip>
            <noise>
                <type>gaussian</type>
                <mean>0.0</mean>
                <stddev>0.007</stddev>
            </noise>
            pose
        </camera>
        <plugin name="camera_controller" filename="libgazebo_ros_camera.so">
            <cameraName>/camera</cameraName>
            <imageTopicName>image_raw</imageTopicName>
            <cameraInfoTopicName>camera_info</cameraInfoTopicName>
            <frameName>camera_link</frameName>
            <hackBaseline>0.07</hackBaseline>
        </plugin>
    </sensor>
    <material>Gazebo/Blue</material>
  </gazebo>

  <!--add_GazeboPlugin-->
  <gazebo>
    <plugin name="gazebo_ros_control" filename="libgazebo_ros_control.so">
      <robotNamespace>/arm_robot</robotNamespace>
      <robotSimType>gazebo_ros_control/DefaultRobotHWSim</robotSimType>
      <legacyModeNS>true</legacyModeNS>
    </plugin>
    <plugin name="joint_state_publisher" filename="libgazebo_ros_joint_state_publisher.so">
      <jointName>arm1_joint, arm2_joint, arm3_joint</jointName>
    </plugin>
  </gazebo>
</robot>

